Workbook
Name Category: #REF!
Name Transaction: #REF!

Sheet Data
B1: PROJECT | C1: TASK | D1: ASIGNEE | E1: START DATE | F1: DAYS REQUIRED | G1: END DATE | H1: PROGRESS | K1: Projects | M1: Resources | O1: TODAY IS:
B2: BASE DE CONNAISSANCE IA OP | C2: Elaboration FAQ | D2: MCCI | E2: 45717 | F2: 13 | G2: =E2+F2 -> 45730 | H2: 1 | K2: BASE DE CONNAISSANCE IA OP | M2: MCCI | O2: 45728 | P2: *) Change to formula =TODAY()
B3: BASE DE CONNAISSANCE IA OP | C3: Elaboration FAQ | D3: MCAM | E3: 45717 | F3: 13 | G3: =E3+F3 -> 45730 | H3: 1 | M3: MCAM
B4: BASE DE CONNAISSANCE IA OP | C4: Elaboration FAQ | D4: MCGB | E4: 45717 | F4: 13 | G4: =E4+F4 -> 45730 | H4: 1 | M4: MCGB
B5: BASE DE CONNAISSANCE IA OP | C5: Elaboration FAQ | D5: MCGC | E5: 45717 | F5: 13 | G5: =E5+F5 -> 45730 | H5: 1 | M5: MCGC
B6: BASE DE CONNAISSANCE IA OP | C6: Elaboration FAQ | D6: MTN B | E6: 45717 | F6: 13 | G6: =E6+F6 -> 45730 | H6: 1 | M6: MTN B
B7: BASE DE CONNAISSANCE IA OP | C7: Elaboration FAQ | D7: CELTIISB | E7: 45717 | F7: 13 | G7: =E7+F7 -> 45730 | H7: 1 | M7: CELTIISB
B8: BASE DE CONNAISSANCE IA OP | C8: Collete et compilation de données | D8: MCCI | E8: 45731 | F8: 2 | G8: =E8+F8 -> 45733 | H8: 1 | M8: OWNER
B9: BASE DE CONNAISSANCE IA OP | C9: Collete et compilation de données | D9: MCAM | E9: 45731 | F9: 2 | G9: =E9+F9 -> 45733 | H9: 1 | M9: DEV
B10: BASE DE CONNAISSANCE IA OP | C10: Collete et compilation de données | D10: MCGB | E10: 45731 | F10: 2 | G10: =E10+F10 -> 45733 | H10: 1
B11: BASE DE CONNAISSANCE IA OP | C11: Collete et compilation de données | D11: MCGC | E11: 45731 | F11: 2 | G11: =E11+F11 -> 45733 | H11: 1
B12: BASE DE CONNAISSANCE IA OP | C12: Collete et compilation de données | D12: MTN B | E12: 45731 | F12: 2 | G12: =E12+F12 -> 45733 | H12: 1 | S12: OVERDUE TASKS
B13: BASE DE CONNAISSANCE IA OP | C13: Collete et compilation de données | D13: CELTIISB | E13: 45731 | F13: 2 | G13: =E13+F13 -> 45733 | H13: 1 | K13: UNFINISHED TASKS | L13: TASK | M13: ASIGNEE | N13: START DATE | O13: DAYS REQUIRED | P13: END DATE | Q13: PROGRESS | S13: PROJECT | T13: TASK | U13: ASIGNEE | V13: START DATE | W13: DAYS REQUIRED | X13: END DATE | Y13: PROGRESS
B14: BASE DE CONNAISSANCE IA OP | C14: Contrôle de la base | D14: OWNER | E14: 45734 | F14: 1 | G14: =E14+F14 -> 45735 | H14: 1 | K14: PROJECT | L14: {=IFERROR(INDEX(Main[],SMALL(IF((Main[PROGRESS]<1),MATCH(ROW(Main[]),ROW(Main[])),""),ROWS($K$14:L14)),COLUMNS($A$1:B1)),"")} -> 0 | M14: {=IFERROR(INDEX(Main[],SMALL(IF((Main[PROGRESS]<1),MATCH(ROW(Main[]),ROW(Main[])),""),ROWS($K$14:M14)),COLUMNS($A$1:C1)),"")} -> DEV | N14: {=IFERROR(INDEX(Main[],SMALL(IF((Main[PROGRESS]<1),MATCH(ROW(Main[]),ROW(Main[])),""),ROWS($K$14:N14)),COLUMNS($A$1:D1)),"")} -> 45737 | O14: {=IFERROR(INDEX(Main[],SMALL(IF((Main[PROGRESS]<1),MATCH(ROW(Main[]),ROW(Main[])),""),ROWS($K$14:O14)),COLUMNS($A$1:E1)),"")} -> 2 | P14: {=IFERROR(INDEX(Main[],SMALL(IF((Main[PROGRESS]<1),MATCH(ROW(Main[]),ROW(Main[])),""),ROWS($K$14:P14)),COLUMNS($A$1:F1)),"")} -> 45739 | Q14: {=IFERROR(INDEX(Main[],SMALL(IF((Main[PROGRESS]<1),MATCH(ROW(Main[]),ROW(Main[])),""),ROWS($K$14:Q14)),COLUMNS($A$1:G1)),"")} -> 0.5 | S14: {=IFERROR(INDEX($K$14:$Q$44,SMALL(IF(($P$14:$P$44<$O$2),MATCH(ROW($K$14:$Q$44),ROW($K$14:$Q$44)),""),ROWS(S$14:$S14)),COLUMNS($A$1:A1)),"")} | T14: {=IFERROR(INDEX($K$14:$Q$44,SMALL(IF(($P$14:$P$44<$O$2),MATCH(ROW($K$14:$Q$44),ROW($K$14:$Q$44)),""),ROWS($S$14:T14)),COLUMNS($A$1:B1)),"")} | U14: {=IFERROR(INDEX($K$14:$Q$44,SMALL(IF(($P$14:$P$44<$O$2),MATCH(ROW($K$14:$Q$44),ROW($K$14:$Q$44)),""),ROWS($S$14:U14)),COLUMNS($A$1:C1)),"")} | V14: {=IFERROR(INDEX($K$14:$Q$44,SMALL(IF(($P$14:$P$44<$O$2),MATCH(ROW($K$14:$Q$44),ROW($K$14:$Q$44)),""),ROWS($S$14:V14)),COLUMNS($A$1:D1)),"")} | W14: {=IFERROR(INDEX($K$14:$Q$44,SMALL(IF(($P$14:$P$44<$O$2),MATCH(ROW($K$14:$Q$44),ROW($K$14:$Q$44)),""),ROWS($S$14:W14)),COLUMNS($A$1:E1)),"")} | X14: {=IFERROR(INDEX($K$14:$Q$44,SMALL(IF(($P$14:$P$44<$O$2),MATCH(ROW($K$14:$Q$44),ROW($K$14:$Q$44)),""),ROWS($S$14:X14)),COLUMNS($A$1:F1)),"")} | Y14: {=IFERROR(INDEX($K$14:$Q$44,SMALL(IF(($P$14:$P$44<$O$2),MATCH(ROW($K$14:$Q$44),ROW($K$14:$Q$44)),""),ROWS($S$14:Y14)),COLUMNS($A$1:G1)),"")}
B15: BASE DE CONNAISSANCE IA OP | C15: Envoi de la base | D15: OWNER | E15: 45735 | F15: 1 | G15: =E15+F15 -> 45736 | H15: 1 | K15: {=IFERROR(INDEX(Main[],SMALL(IF((Main[PROGRESS]<1),MATCH(ROW(Main[]),ROW(Main[])),""),ROWS(K$15:$K15)),COLUMNS($A$1:A1)),"")} -> BASE DE CONNAISSANCE IA OP | L15: {=IFERROR(INDEX(Main[],SMALL(IF((Main[PROGRESS]<1),MATCH(ROW(Main[]),ROW(Main[])),""),ROWS($K$14:L15)),COLUMNS($A$1:B2)),"")} -> 0 | M15: {=IFERROR(INDEX(Main[],SMALL(IF((Main[PROGRESS]<1),MATCH(ROW(Main[]),ROW(Main[])),""),ROWS($K$14:M15)),COLUMNS($A$1:C2)),"")} -> DEV | N15: {=IFERROR(INDEX(Main[],SMALL(IF((Main[PROGRESS]<1),MATCH(ROW(Main[]),ROW(Main[])),""),ROWS($K$14:N15)),COLUMNS($A$1:D2)),"")} -> 45737 | O15: {=IFERROR(INDEX(Main[],SMALL(IF((Main[PROGRESS]<1),MATCH(ROW(Main[]),ROW(Main[])),""),ROWS($K$14:O15)),COLUMNS($A$1:E2)),"")} -> 1 | P15: {=IFERROR(INDEX(Main[],SMALL(IF((Main[PROGRESS]<1),MATCH(ROW(Main[]),ROW(Main[])),""),ROWS($K$14:P15)),COLUMNS($A$1:F2)),"")} -> 45738 | Q15: {=IFERROR(INDEX(Main[],SMALL(IF((Main[PROGRESS]<1),MATCH(ROW(Main[]),ROW(Main[])),""),ROWS($K$14:Q15)),COLUMNS($A$1:G2)),"")} -> 0.5 | S15: {=IFERROR(INDEX($K$14:$Q$44,SMALL(IF(($P$14:$P$44<$O$2),MATCH(ROW($K$14:$Q$44),ROW($K$14:$Q$44)),""),ROWS(S$14:$S15)),COLUMNS($A$1:A2)),"")} | T15: {=IFERROR(INDEX($K$14:$Q$44,SMALL(IF(($P$14:$P$44<$O$2),MATCH(ROW($K$14:$Q$44),ROW($K$14:$Q$44)),""),ROWS($S$14:T15)),COLUMNS($A$1:B2)),"")} | U15: {=IFERROR(INDEX($K$14:$Q$44,SMALL(IF(($P$14:$P$44<$O$2),MATCH(ROW($K$14:$Q$44),ROW($K$14:$Q$44)),""),ROWS($S$14:U15)),COLUMNS($A$1:C2)),"")} | V15: {=IFERROR(INDEX($K$14:$Q$44,SMALL(IF(($P$14:$P$44<$O$2),MATCH(ROW($K$14:$Q$44),ROW($K$14:$Q$44)),""),ROWS($S$14:V15)),COLUMNS($A$1:D2)),"")} | W15: {=IFERROR(INDEX($K$14:$Q$44,SMALL(IF(($P$14:$P$44<$O$2),MATCH(ROW($K$14:$Q$44),ROW($K$14:$Q$44)),""),ROWS($S$14:W15)),COLUMNS($A$1:E2)),"")} | X15: {=IFERROR(INDEX($K$14:$Q$44,SMALL(IF(($P$14:$P$44<$O$2),MATCH(ROW($K$14:$Q$44),ROW($K$14:$Q$44)),""),ROWS($S$14:X15)),COLUMNS($A$1:F2)),"")} | Y15: {=IFERROR(INDEX($K$14:$Q$44,SMALL(IF(($P$14:$P$44<$O$2),MATCH(ROW($K$14:$Q$44),ROW($K$14:$Q$44)),""),ROWS($S$14:Y15)),COLUMNS($A$1:G2)),"")}
B16: BASE DE CONNAISSANCE IA OP | D16: DEV | E16: 45737 | F16: 2 | G16: =E16+F16 -> 45739 | H16: 0.5 | K16: {=IFERROR(INDEX(Main[],SMALL(IF((Main[PROGRESS]<1),MATCH(ROW(Main[]),ROW(Main[])),""),ROWS(K$15:$K16)),COLUMNS($A$1:A2)),"")} -> BASE DE CONNAISSANCE IA OP | L16: {=IFERROR(INDEX(Main[],SMALL(IF((Main[PROGRESS]<1),MATCH(ROW(Main[]),ROW(Main[])),""),ROWS($K$14:L16)),COLUMNS($A$1:B3)),"")} -> 0 | M16: {=IFERROR(INDEX(Main[],SMALL(IF((Main[PROGRESS]<1),MATCH(ROW(Main[]),ROW(Main[])),""),ROWS($K$14:M16)),COLUMNS($A$1:C3)),"")} -> DEV | N16: {=IFERROR(INDEX(Main[],SMALL(IF((Main[PROGRESS]<1),MATCH(ROW(Main[]),ROW(Main[])),""),ROWS($K$14:N16)),COLUMNS($A$1:D3)),"")} -> 45738 | O16: {=IFERROR(INDEX(Main[],SMALL(IF((Main[PROGRESS]<1),MATCH(ROW(Main[]),ROW(Main[])),""),ROWS($K$14:O16)),COLUMNS($A$1:E3)),"")} -> 4 | P16: {=IFERROR(INDEX(Main[],SMALL(IF((Main[PROGRESS]<1),MATCH(ROW(Main[]),ROW(Main[])),""),ROWS($K$14:P16)),COLUMNS($A$1:F3)),"")} -> 45742 | Q16: {=IFERROR(INDEX(Main[],SMALL(IF((Main[PROGRESS]<1),MATCH(ROW(Main[]),ROW(Main[])),""),ROWS($K$14:Q16)),COLUMNS($A$1:G3)),"")} -> 0.5 | S16: {=IFERROR(INDEX($K$14:$Q$44,SMALL(IF(($P$14:$P$44<$O$2),MATCH(ROW($K$14:$Q$44),ROW($K$14:$Q$44)),""),ROWS(S$14:$S16)),COLUMNS($A$1:A3)),"")} | T16: {=IFERROR(INDEX($K$14:$Q$44,SMALL(IF(($P$14:$P$44<$O$2),MATCH(ROW($K$14:$Q$44),ROW($K$14:$Q$44)),""),ROWS($S$14:T16)),COLUMNS($A$1:B3)),"")} | U16: {=IFERROR(INDEX($K$14:$Q$44,SMALL(IF(($P$14:$P$44<$O$2),MATCH(ROW($K$14:$Q$44),ROW($K$14:$Q$44)),""),ROWS($S$14:U16)),COLUMNS($A$1:C3)),"")} | V16: {=IFERROR(INDEX($K$14:$Q$44,SMALL(IF(($P$14:$P$44<$O$2),MATCH(ROW($K$14:$Q$44),ROW($K$14:$Q$44)),""),ROWS($S$14:V16)),COLUMNS($A$1:D3)),"")} | W16: {=IFERROR(INDEX($K$14:$Q$44,SMALL(IF(($P$14:$P$44<$O$2),MATCH(ROW($K$14:$Q$44),ROW($K$14:$Q$44)),""),ROWS($S$14:W16)),COLUMNS($A$1:E3)),"")} | X16: {=IFERROR(INDEX($K$14:$Q$44,SMALL(IF(($P$14:$P$44<$O$2),MATCH(ROW($K$14:$Q$44),ROW($K$14:$Q$44)),""),ROWS($S$14:X16)),COLUMNS($A$1:F3)),"")} | Y16: {=IFERROR(INDEX($K$14:$Q$44,SMALL(IF(($P$14:$P$44<$O$2),MATCH(ROW($K$14:$Q$44),ROW($K$14:$Q$44)),""),ROWS($S$14:Y16)),COLUMNS($A$1:G3)),"")}
B17: BASE DE CONNAISSANCE IA OP | D17: DEV | E17: 45737 | F17: 1 | G17: =E17+F17 -> 45738 | H17: 0.5 | K17: {=IFERROR(INDEX(Main[],SMALL(IF((Main[PROGRESS]<1),MATCH(ROW(Main[]),ROW(Main[])),""),ROWS(K$15:$K17)),COLUMNS($A$1:A3)),"")} -> BASE DE CONNAISSANCE IA OP | L17: {=IFERROR(INDEX(Main[],SMALL(IF((Main[PROGRESS]<1),MATCH(ROW(Main[]),ROW(Main[])),""),ROWS($K$14:L17)),COLUMNS($A$1:B4)),"")} -> 0 | M17: {=IFERROR(INDEX(Main[],SMALL(IF((Main[PROGRESS]<1),MATCH(ROW(Main[]),ROW(Main[])),""),ROWS($K$14:M17)),COLUMNS($A$1:C4)),"")} -> DEV | N17: {=IFERROR(INDEX(Main[],SMALL(IF((Main[PROGRESS]<1),MATCH(ROW(Main[]),ROW(Main[])),""),ROWS($K$14:N17)),COLUMNS($A$1:D4)),"")} -> 45739 | O17: {=IFERROR(INDEX(Main[],SMALL(IF((Main[PROGRESS]<1),MATCH(ROW(Main[]),ROW(Main[])),""),ROWS($K$14:O17)),COLUMNS($A$1:E4)),"")} -> 1 | P17: {=IFERROR(INDEX(Main[],SMALL(IF((Main[PROGRESS]<1),MATCH(ROW(Main[]),ROW(Main[])),""),ROWS($K$14:P17)),COLUMNS($A$1:F4)),"")} -> 45740 | Q17: {=IFERROR(INDEX(Main[],SMALL(IF((Main[PROGRESS]<1),MATCH(ROW(Main[]),ROW(Main[])),""),ROWS($K$14:Q17)),COLUMNS($A$1:G4)),"")} -> 0.5 | S17: {=IFERROR(INDEX($K$14:$Q$44,SMALL(IF(($P$14:$P$44<$O$2),MATCH(ROW($K$14:$Q$44),ROW($K$14:$Q$44)),""),ROWS(S$14:$S17)),COLUMNS($A$1:A4)),"")} | T17: {=IFERROR(INDEX($K$14:$Q$44,SMALL(IF(($P$14:$P$44<$O$2),MATCH(ROW($K$14:$Q$44),ROW($K$14:$Q$44)),""),ROWS($S$14:T17)),COLUMNS($A$1:B4)),"")} | U17: {=IFERROR(INDEX($K$14:$Q$44,SMALL(IF(($P$14:$P$44<$O$2),MATCH(ROW($K$14:$Q$44),ROW($K$14:$Q$44)),""),ROWS($S$14:U17)),COLUMNS($A$1:C4)),"")} | V17: {=IFERROR(INDEX($K$14:$Q$44,SMALL(IF(($P$14:$P$44<$O$2),MATCH(ROW($K$14:$Q$44),ROW($K$14:$Q$44)),""),ROWS($S$14:V17)),COLUMNS($A$1:D4)),"")} | W17: {=IFERROR(INDEX($K$14:$Q$44,SMALL(IF(($P$14:$P$44<$O$2),MATCH(ROW($K$14:$Q$44),ROW($K$14:$Q$44)),""),ROWS($S$14:W17)),COLUMNS($A$1:E4)),"")} | X17: {=IFERROR(INDEX($K$14:$Q$44,SMALL(IF(($P$14:$P$44<$O$2),MATCH(ROW($K$14:$Q$44),ROW($K$14:$Q$44)),""),ROWS($S$14:X17)),COLUMNS($A$1:F4)),"")} | Y17: {=IFERROR(INDEX($K$14:$Q$44,SMALL(IF(($P$14:$P$44<$O$2),MATCH(ROW($K$14:$Q$44),ROW($K$14:$Q$44)),""),ROWS($S$14:Y17)),COLUMNS($A$1:G4)),"")}
B18: BASE DE CONNAISSANCE IA OP | D18: DEV | E18: 45738 | F18: 4 | G18: =E18+F18 -> 45742 | H18: 0.5 | K18: {=IFERROR(INDEX(Main[],SMALL(IF((Main[PROGRESS]<1),MATCH(ROW(Main[]),ROW(Main[])),""),ROWS(K$15:$K18)),COLUMNS($A$1:A4)),"")} -> BASE DE CONNAISSANCE IA OP | L18: {=IFERROR(INDEX(Main[],SMALL(IF((Main[PROGRESS]<1),MATCH(ROW(Main[]),ROW(Main[])),""),ROWS($K$14:L18)),COLUMNS($A$1:B5)),"")} -> 0 | M18: {=IFERROR(INDEX(Main[],SMALL(IF((Main[PROGRESS]<1),MATCH(ROW(Main[]),ROW(Main[])),""),ROWS($K$14:M18)),COLUMNS($A$1:C5)),"")} -> DEV | N18: {=IFERROR(INDEX(Main[],SMALL(IF((Main[PROGRESS]<1),MATCH(ROW(Main[]),ROW(Main[])),""),ROWS($K$14:N18)),COLUMNS($A$1:D5)),"")} -> 45740 | O18: {=IFERROR(INDEX(Main[],SMALL(IF((Main[PROGRESS]<1),MATCH(ROW(Main[]),ROW(Main[])),""),ROWS($K$14:O18)),COLUMNS($A$1:E5)),"")} -> 1 | P18: {=IFERROR(INDEX(Main[],SMALL(IF((Main[PROGRESS]<1),MATCH(ROW(Main[]),ROW(Main[])),""),ROWS($K$14:P18)),COLUMNS($A$1:F5)),"")} -> 45741 | Q18: {=IFERROR(INDEX(Main[],SMALL(IF((Main[PROGRESS]<1),MATCH(ROW(Main[]),ROW(Main[])),""),ROWS($K$14:Q18)),COLUMNS($A$1:G5)),"")} -> 0.5 | S18: {=IFERROR(INDEX($K$14:$Q$44,SMALL(IF(($P$14:$P$44<$O$2),MATCH(ROW($K$14:$Q$44),ROW($K$14:$Q$44)),""),ROWS(S$14:$S18)),COLUMNS($A$1:A5)),"")} | T18: {=IFERROR(INDEX($K$14:$Q$44,SMALL(IF(($P$14:$P$44<$O$2),MATCH(ROW($K$14:$Q$44),ROW($K$14:$Q$44)),""),ROWS($S$14:T18)),COLUMNS($A$1:B5)),"")} | U18: {=IFERROR(INDEX($K$14:$Q$44,SMALL(IF(($P$14:$P$44<$O$2),MATCH(ROW($K$14:$Q$44),ROW($K$14:$Q$44)),""),ROWS($S$14:U18)),COLUMNS($A$1:C5)),"")} | V18: {=IFERROR(INDEX($K$14:$Q$44,SMALL(IF(($P$14:$P$44<$O$2),MATCH(ROW($K$14:$Q$44),ROW($K$14:$Q$44)),""),ROWS($S$14:V18)),COLUMNS($A$1:D5)),"")} | W18: {=IFERROR(INDEX($K$14:$Q$44,SMALL(IF(($P$14:$P$44<$O$2),MATCH(ROW($K$14:$Q$44),ROW($K$14:$Q$44)),""),ROWS($S$14:W18)),COLUMNS($A$1:E5)),"")} | X18: {=IFERROR(INDEX($K$14:$Q$44,SMALL(IF(($P$14:$P$44<$O$2),MATCH(ROW($K$14:$Q$44),ROW($K$14:$Q$44)),""),ROWS($S$14:X18)),COLUMNS($A$1:F5)),"")} | Y18: {=IFERROR(INDEX($K$14:$Q$44,SMALL(IF(($P$14:$P$44<$O$2),MATCH(ROW($K$14:$Q$44),ROW($K$14:$Q$44)),""),ROWS($S$14:Y18)),COLUMNS($A$1:G5)),"")}
B19: BASE DE CONNAISSANCE IA OP | D19: DEV | E19: 45739 | F19: 1 | G19: =E19+F19 -> 45740 | H19: 0.5 | K19: {=IFERROR(INDEX(Main[],SMALL(IF((Main[PROGRESS]<1),MATCH(ROW(Main[]),ROW(Main[])),""),ROWS(K$15:$K19)),COLUMNS($A$1:A5)),"")} -> BASE DE CONNAISSANCE IA OP | L19: {=IFERROR(INDEX(Main[],SMALL(IF((Main[PROGRESS]<1),MATCH(ROW(Main[]),ROW(Main[])),""),ROWS($K$14:L19)),COLUMNS($A$1:B6)),"")} -> 0 | M19: {=IFERROR(INDEX(Main[],SMALL(IF((Main[PROGRESS]<1),MATCH(ROW(Main[]),ROW(Main[])),""),ROWS($K$14:M19)),COLUMNS($A$1:C6)),"")} -> DEV | N19: {=IFERROR(INDEX(Main[],SMALL(IF((Main[PROGRESS]<1),MATCH(ROW(Main[]),ROW(Main[])),""),ROWS($K$14:N19)),COLUMNS($A$1:D6)),"")} -> 45741 | O19: {=IFERROR(INDEX(Main[],SMALL(IF((Main[PROGRESS]<1),MATCH(ROW(Main[]),ROW(Main[])),""),ROWS($K$14:O19)),COLUMNS($A$1:E6)),"")} -> 7 | P19: {=IFERROR(INDEX(Main[],SMALL(IF((Main[PROGRESS]<1),MATCH(ROW(Main[]),ROW(Main[])),""),ROWS($K$14:P19)),COLUMNS($A$1:F6)),"")} -> 45748 | Q19: {=IFERROR(INDEX(Main[],SMALL(IF((Main[PROGRESS]<1),MATCH(ROW(Main[]),ROW(Main[])),""),ROWS($K$14:Q19)),COLUMNS($A$1:G6)),"")} -> 0.5 | S19: {=IFERROR(INDEX($K$14:$Q$44,SMALL(IF(($P$14:$P$44<$O$2),MATCH(ROW($K$14:$Q$44),ROW($K$14:$Q$44)),""),ROWS(S$14:$S19)),COLUMNS($A$1:A6)),"")} | T19: {=IFERROR(INDEX($K$14:$Q$44,SMALL(IF(($P$14:$P$44<$O$2),MATCH(ROW($K$14:$Q$44),ROW($K$14:$Q$44)),""),ROWS($S$14:T19)),COLUMNS($A$1:B6)),"")} | U19: {=IFERROR(INDEX($K$14:$Q$44,SMALL(IF(($P$14:$P$44<$O$2),MATCH(ROW($K$14:$Q$44),ROW($K$14:$Q$44)),""),ROWS($S$14:U19)),COLUMNS($A$1:C6)),"")} | V19: {=IFERROR(INDEX($K$14:$Q$44,SMALL(IF(($P$14:$P$44<$O$2),MATCH(ROW($K$14:$Q$44),ROW($K$14:$Q$44)),""),ROWS($S$14:V19)),COLUMNS($A$1:D6)),"")} | W19: {=IFERROR(INDEX($K$14:$Q$44,SMALL(IF(($P$14:$P$44<$O$2),MATCH(ROW($K$14:$Q$44),ROW($K$14:$Q$44)),""),ROWS($S$14:W19)),COLUMNS($A$1:E6)),"")} | X19: {=IFERROR(INDEX($K$14:$Q$44,SMALL(IF(($P$14:$P$44<$O$2),MATCH(ROW($K$14:$Q$44),ROW($K$14:$Q$44)),""),ROWS($S$14:X19)),COLUMNS($A$1:F6)),"")} | Y19: {=IFERROR(INDEX($K$14:$Q$44,SMALL(IF(($P$14:$P$44<$O$2),MATCH(ROW($K$14:$Q$44),ROW($K$14:$Q$44)),""),ROWS($S$14:Y19)),COLUMNS($A$1:G6)),"")}
B20: BASE DE CONNAISSANCE IA OP | D20: DEV | E20: 45740 | F20: 1 | G20: =E20+F20 -> 45741 | H20: 0.5 | K20: {=IFERROR(INDEX(Main[],SMALL(IF((Main[PROGRESS]<1),MATCH(ROW(Main[]),ROW(Main[])),""),ROWS(K$15:$K20)),COLUMNS($A$1:A6)),"")} -> BASE DE CONNAISSANCE IA OP | L20: {=IFERROR(INDEX(Main[],SMALL(IF((Main[PROGRESS]<1),MATCH(ROW(Main[]),ROW(Main[])),""),ROWS($K$14:L20)),COLUMNS($A$1:B7)),"")} -> 0 | M20: {=IFERROR(INDEX(Main[],SMALL(IF((Main[PROGRESS]<1),MATCH(ROW(Main[]),ROW(Main[])),""),ROWS($K$14:M20)),COLUMNS($A$1:C7)),"")} -> DEV | N20: {=IFERROR(INDEX(Main[],SMALL(IF((Main[PROGRESS]<1),MATCH(ROW(Main[]),ROW(Main[])),""),ROWS($K$14:N20)),COLUMNS($A$1:D7)),"")} -> 45742 | O20: {=IFERROR(INDEX(Main[],SMALL(IF((Main[PROGRESS]<1),MATCH(ROW(Main[]),ROW(Main[])),""),ROWS($K$14:O20)),COLUMNS($A$1:E7)),"")} -> 4 | P20: {=IFERROR(INDEX(Main[],SMALL(IF((Main[PROGRESS]<1),MATCH(ROW(Main[]),ROW(Main[])),""),ROWS($K$14:P20)),COLUMNS($A$1:F7)),"")} -> 45746 | Q20: {=IFERROR(INDEX(Main[],SMALL(IF((Main[PROGRESS]<1),MATCH(ROW(Main[]),ROW(Main[])),""),ROWS($K$14:Q20)),COLUMNS($A$1:G7)),"")} -> 0.5 | S20: {=IFERROR(INDEX($K$14:$Q$44,SMALL(IF(($P$14:$P$44<$O$2),MATCH(ROW($K$14:$Q$44),ROW($K$14:$Q$44)),""),ROWS(S$14:$S20)),COLUMNS($A$1:A7)),"")} | T20: {=IFERROR(INDEX($K$14:$Q$44,SMALL(IF(($P$14:$P$44<$O$2),MATCH(ROW($K$14:$Q$44),ROW($K$14:$Q$44)),""),ROWS($S$14:T20)),COLUMNS($A$1:B7)),"")} | U20: {=IFERROR(INDEX($K$14:$Q$44,SMALL(IF(($P$14:$P$44<$O$2),MATCH(ROW($K$14:$Q$44),ROW($K$14:$Q$44)),""),ROWS($S$14:U20)),COLUMNS($A$1:C7)),"")} | V20: {=IFERROR(INDEX($K$14:$Q$44,SMALL(IF(($P$14:$P$44<$O$2),MATCH(ROW($K$14:$Q$44),ROW($K$14:$Q$44)),""),ROWS($S$14:V20)),COLUMNS($A$1:D7)),"")} | W20: {=IFERROR(INDEX($K$14:$Q$44,SMALL(IF(($P$14:$P$44<$O$2),MATCH(ROW($K$14:$Q$44),ROW($K$14:$Q$44)),""),ROWS($S$14:W20)),COLUMNS($A$1:E7)),"")} | X20: {=IFERROR(INDEX($K$14:$Q$44,SMALL(IF(($P$14:$P$44<$O$2),MATCH(ROW($K$14:$Q$44),ROW($K$14:$Q$44)),""),ROWS($S$14:X20)),COLUMNS($A$1:F7)),"")} | Y20: {=IFERROR(INDEX($K$14:$Q$44,SMALL(IF(($P$14:$P$44<$O$2),MATCH(ROW($K$14:$Q$44),ROW($K$14:$Q$44)),""),ROWS($S$14:Y20)),COLUMNS($A$1:G7)),"")}
B21: BASE DE CONNAISSANCE IA OP | D21: DEV | E21: 45741 | F21: 7 | G21: =E21+F21 -> 45748 | H21: 0.5 | K21: {=IFERROR(INDEX(Main[],SMALL(IF((Main[PROGRESS]<1),MATCH(ROW(Main[]),ROW(Main[])),""),ROWS(K$15:$K21)),COLUMNS($A$1:A7)),"")} -> BASE DE CONNAISSANCE IA OP | L21: {=IFERROR(INDEX(Main[],SMALL(IF((Main[PROGRESS]<1),MATCH(ROW(Main[]),ROW(Main[])),""),ROWS($K$14:L21)),COLUMNS($A$1:B8)),"")} | M21: {=IFERROR(INDEX(Main[],SMALL(IF((Main[PROGRESS]<1),MATCH(ROW(Main[]),ROW(Main[])),""),ROWS($K$14:M21)),COLUMNS($A$1:C8)),"")} | N21: {=IFERROR(INDEX(Main[],SMALL(IF((Main[PROGRESS]<1),MATCH(ROW(Main[]),ROW(Main[])),""),ROWS($K$14:N21)),COLUMNS($A$1:D8)),"")} | O21: {=IFERROR(INDEX(Main[],SMALL(IF((Main[PROGRESS]<1),MATCH(ROW(Main[]),ROW(Main[])),""),ROWS($K$14:O21)),COLUMNS($A$1:E8)),"")} | P21: {=IFERROR(INDEX(Main[],SMALL(IF((Main[PROGRESS]<1),MATCH(ROW(Main[]),ROW(Main[])),""),ROWS($K$14:P21)),COLUMNS($A$1:F8)),"")} | Q21: {=IFERROR(INDEX(Main[],SMALL(IF((Main[PROGRESS]<1),MATCH(ROW(Main[]),ROW(Main[])),""),ROWS($K$14:Q21)),COLUMNS($A$1:G8)),"")} | S21: {=IFERROR(INDEX($K$14:$Q$44,SMALL(IF(($P$14:$P$44<$O$2),MATCH(ROW($K$14:$Q$44),ROW($K$14:$Q$44)),""),ROWS(S$14:$S21)),COLUMNS($A$1:A8)),"")} | T21: {=IFERROR(INDEX($K$14:$Q$44,SMALL(IF(($P$14:$P$44<$O$2),MATCH(ROW($K$14:$Q$44),ROW($K$14:$Q$44)),""),ROWS($S$14:T21)),COLUMNS($A$1:B8)),"")} | U21: {=IFERROR(INDEX($K$14:$Q$44,SMALL(IF(($P$14:$P$44<$O$2),MATCH(ROW($K$14:$Q$44),ROW($K$14:$Q$44)),""),ROWS($S$14:U21)),COLUMNS($A$1:C8)),"")} | V21: {=IFERROR(INDEX($K$14:$Q$44,SMALL(IF(($P$14:$P$44<$O$2),MATCH(ROW($K$14:$Q$44),ROW($K$14:$Q$44)),""),ROWS($S$14:V21)),COLUMNS($A$1:D8)),"")} | W21: {=IFERROR(INDEX($K$14:$Q$44,SMALL(IF(($P$14:$P$44<$O$2),MATCH(ROW($K$14:$Q$44),ROW($K$14:$Q$44)),""),ROWS($S$14:W21)),COLUMNS($A$1:E8)),"")} | X21: {=IFERROR(INDEX($K$14:$Q$44,SMALL(IF(($P$14:$P$44<$O$2),MATCH(ROW($K$14:$Q$44),ROW($K$14:$Q$44)),""),ROWS($S$14:X21)),COLUMNS($A$1:F8)),"")} | Y21: {=IFERROR(INDEX($K$14:$Q$44,SMALL(IF(($P$14:$P$44<$O$2),MATCH(ROW($K$14:$Q$44),ROW($K$14:$Q$44)),""),ROWS($S$14:Y21)),COLUMNS($A$1:G8)),"")}
B22: BASE DE CONNAISSANCE IA OP | D22: DEV | E22: 45742 | F22: 4 | G22: =E22+F22 -> 45746 | H22: 0.5 | K22: {=IFERROR(INDEX(Main[],SMALL(IF((Main[PROGRESS]<1),MATCH(ROW(Main[]),ROW(Main[])),""),ROWS(K$15:$K22)),COLUMNS($A$1:A8)),"")} | L22: {=IFERROR(INDEX(Main[],SMALL(IF((Main[PROGRESS]<1),MATCH(ROW(Main[]),ROW(Main[])),""),ROWS($K$14:L22)),COLUMNS($A$1:B9)),"")} | M22: {=IFERROR(INDEX(Main[],SMALL(IF((Main[PROGRESS]<1),MATCH(ROW(Main[]),ROW(Main[])),""),ROWS($K$14:M22)),COLUMNS($A$1:C9)),"")} | N22: {=IFERROR(INDEX(Main[],SMALL(IF((Main[PROGRESS]<1),MATCH(ROW(Main[]),ROW(Main[])),""),ROWS($K$14:N22)),COLUMNS($A$1:D9)),"")} | O22: {=IFERROR(INDEX(Main[],SMALL(IF((Main[PROGRESS]<1),MATCH(ROW(Main[]),ROW(Main[])),""),ROWS($K$14:O22)),COLUMNS($A$1:E9)),"")} | P22: {=IFERROR(INDEX(Main[],SMALL(IF((Main[PROGRESS]<1),MATCH(ROW(Main[]),ROW(Main[])),""),ROWS($K$14:P22)),COLUMNS($A$1:F9)),"")} | Q22: {=IFERROR(INDEX(Main[],SMALL(IF((Main[PROGRESS]<1),MATCH(ROW(Main[]),ROW(Main[])),""),ROWS($K$14:Q22)),COLUMNS($A$1:G9)),"")} | S22: {=IFERROR(INDEX($K$14:$Q$44,SMALL(IF(($P$14:$P$44<$O$2),MATCH(ROW($K$14:$Q$44),ROW($K$14:$Q$44)),""),ROWS(S$14:$S22)),COLUMNS($A$1:A9)),"")} | T22: {=IFERROR(INDEX($K$14:$Q$44,SMALL(IF(($P$14:$P$44<$O$2),MATCH(ROW($K$14:$Q$44),ROW($K$14:$Q$44)),""),ROWS($S$14:T22)),COLUMNS($A$1:B9)),"")} | U22: {=IFERROR(INDEX($K$14:$Q$44,SMALL(IF(($P$14:$P$44<$O$2),MATCH(ROW($K$14:$Q$44),ROW($K$14:$Q$44)),""),ROWS($S$14:U22)),COLUMNS($A$1:C9)),"")} | V22: {=IFERROR(INDEX($K$14:$Q$44,SMALL(IF(($P$14:$P$44<$O$2),MATCH(ROW($K$14:$Q$44),ROW($K$14:$Q$44)),""),ROWS($S$14:V22)),COLUMNS($A$1:D9)),"")} | W22: {=IFERROR(INDEX($K$14:$Q$44,SMALL(IF(($P$14:$P$44<$O$2),MATCH(ROW($K$14:$Q$44),ROW($K$14:$Q$44)),""),ROWS($S$14:W22)),COLUMNS($A$1:E9)),"")} | X22: {=IFERROR(INDEX($K$14:$Q$44,SMALL(IF(($P$14:$P$44<$O$2),MATCH(ROW($K$14:$Q$44),ROW($K$14:$Q$44)),""),ROWS($S$14:X22)),COLUMNS($A$1:F9)),"")} | Y22: {=IFERROR(INDEX($K$14:$Q$44,SMALL(IF(($P$14:$P$44<$O$2),MATCH(ROW($K$14:$Q$44),ROW($K$14:$Q$44)),""),ROWS($S$14:Y22)),COLUMNS($A$1:G9)),"")}
K23: {=IFERROR(INDEX(Main[],SMALL(IF((Main[PROGRESS]<1),MATCH(ROW(Main[]),ROW(Main[])),""),ROWS(K$15:$K23)),COLUMNS($A$1:A9)),"")} | L23: {=IFERROR(INDEX(Main[],SMALL(IF((Main[PROGRESS]<1),MATCH(ROW(Main[]),ROW(Main[])),""),ROWS($K$14:L23)),COLUMNS($A$1:B10)),"")} | M23: {=IFERROR(INDEX(Main[],SMALL(IF((Main[PROGRESS]<1),MATCH(ROW(Main[]),ROW(Main[])),""),ROWS($K$14:M23)),COLUMNS($A$1:C10)),"")} | N23: {=IFERROR(INDEX(Main[],SMALL(IF((Main[PROGRESS]<1),MATCH(ROW(Main[]),ROW(Main[])),""),ROWS($K$14:N23)),COLUMNS($A$1:D10)),"")} | O23: {=IFERROR(INDEX(Main[],SMALL(IF((Main[PROGRESS]<1),MATCH(ROW(Main[]),ROW(Main[])),""),ROWS($K$14:O23)),COLUMNS($A$1:E10)),"")} | P23: {=IFERROR(INDEX(Main[],SMALL(IF((Main[PROGRESS]<1),MATCH(ROW(Main[]),ROW(Main[])),""),ROWS($K$14:P23)),COLUMNS($A$1:F10)),"")} | Q23: {=IFERROR(INDEX(Main[],SMALL(IF((Main[PROGRESS]<1),MATCH(ROW(Main[]),ROW(Main[])),""),ROWS($K$14:Q23)),COLUMNS($A$1:G10)),"")} | S23: {=IFERROR(INDEX($K$14:$Q$44,SMALL(IF(($P$14:$P$44<$O$2),MATCH(ROW($K$14:$Q$44),ROW($K$14:$Q$44)),""),ROWS(S$14:$S23)),COLUMNS($A$1:A10)),"")} | T23: {=IFERROR(INDEX($K$14:$Q$44,SMALL(IF(($P$14:$P$44<$O$2),MATCH(ROW($K$14:$Q$44),ROW($K$14:$Q$44)),""),ROWS($S$14:T23)),COLUMNS($A$1:B10)),"")} | U23: {=IFERROR(INDEX($K$14:$Q$44,SMALL(IF(($P$14:$P$44<$O$2),MATCH(ROW($K$14:$Q$44),ROW($K$14:$Q$44)),""),ROWS($S$14:U23)),COLUMNS($A$1:C10)),"")} | V23: {=IFERROR(INDEX($K$14:$Q$44,SMALL(IF(($P$14:$P$44<$O$2),MATCH(ROW($K$14:$Q$44),ROW($K$14:$Q$44)),""),ROWS($S$14:V23)),COLUMNS($A$1:D10)),"")} | W23: {=IFERROR(INDEX($K$14:$Q$44,SMALL(IF(($P$14:$P$44<$O$2),MATCH(ROW($K$14:$Q$44),ROW($K$14:$Q$44)),""),ROWS($S$14:W23)),COLUMNS($A$1:E10)),"")} | X23: {=IFERROR(INDEX($K$14:$Q$44,SMALL(IF(($P$14:$P$44<$O$2),MATCH(ROW($K$14:$Q$44),ROW($K$14:$Q$44)),""),ROWS($S$14:X23)),COLUMNS($A$1:F10)),"")} | Y23: {=IFERROR(INDEX($K$14:$Q$44,SMALL(IF(($P$14:$P$44<$O$2),MATCH(ROW($K$14:$Q$44),ROW($K$14:$Q$44)),""),ROWS($S$14:Y23)),COLUMNS($A$1:G10)),"")}
K24: {=IFERROR(INDEX(Main[],SMALL(IF((Main[PROGRESS]<1),MATCH(ROW(Main[]),ROW(Main[])),""),ROWS(K$15:$K24)),COLUMNS($A$1:A10)),"")} | L24: {=IFERROR(INDEX(Main[],SMALL(IF((Main[PROGRESS]<1),MATCH(ROW(Main[]),ROW(Main[])),""),ROWS($K$14:L24)),COLUMNS($A$1:B11)),"")} | M24: {=IFERROR(INDEX(Main[],SMALL(IF((Main[PROGRESS]<1),MATCH(ROW(Main[]),ROW(Main[])),""),ROWS($K$14:M24)),COLUMNS($A$1:C11)),"")} | N24: {=IFERROR(INDEX(Main[],SMALL(IF((Main[PROGRESS]<1),MATCH(ROW(Main[]),ROW(Main[])),""),ROWS($K$14:N24)),COLUMNS($A$1:D11)),"")} | O24: {=IFERROR(INDEX(Main[],SMALL(IF((Main[PROGRESS]<1),MATCH(ROW(Main[]),ROW(Main[])),""),ROWS($K$14:O24)),COLUMNS($A$1:E11)),"")} | P24: {=IFERROR(INDEX(Main[],SMALL(IF((Main[PROGRESS]<1),MATCH(ROW(Main[]),ROW(Main[])),""),ROWS($K$14:P24)),COLUMNS($A$1:F11)),"")} | Q24: {=IFERROR(INDEX(Main[],SMALL(IF((Main[PROGRESS]<1),MATCH(ROW(Main[]),ROW(Main[])),""),ROWS($K$14:Q24)),COLUMNS($A$1:G11)),"")} | S24: {=IFERROR(INDEX($K$14:$Q$44,SMALL(IF(($P$14:$P$44<$O$2),MATCH(ROW($K$14:$Q$44),ROW($K$14:$Q$44)),""),ROWS(S$14:$S24)),COLUMNS($A$1:A11)),"")} | T24: {=IFERROR(INDEX($K$14:$Q$44,SMALL(IF(($P$14:$P$44<$O$2),MATCH(ROW($K$14:$Q$44),ROW($K$14:$Q$44)),""),ROWS($S$14:T24)),COLUMNS($A$1:B11)),"")} | U24: {=IFERROR(INDEX($K$14:$Q$44,SMALL(IF(($P$14:$P$44<$O$2),MATCH(ROW($K$14:$Q$44),ROW($K$14:$Q$44)),""),ROWS($S$14:U24)),COLUMNS($A$1:C11)),"")} | V24: {=IFERROR(INDEX($K$14:$Q$44,SMALL(IF(($P$14:$P$44<$O$2),MATCH(ROW($K$14:$Q$44),ROW($K$14:$Q$44)),""),ROWS($S$14:V24)),COLUMNS($A$1:D11)),"")} | W24: {=IFERROR(INDEX($K$14:$Q$44,SMALL(IF(($P$14:$P$44<$O$2),MATCH(ROW($K$14:$Q$44),ROW($K$14:$Q$44)),""),ROWS($S$14:W24)),COLUMNS($A$1:E11)),"")} | X24: {=IFERROR(INDEX($K$14:$Q$44,SMALL(IF(($P$14:$P$44<$O$2),MATCH(ROW($K$14:$Q$44),ROW($K$14:$Q$44)),""),ROWS($S$14:X24)),COLUMNS($A$1:F11)),"")} | Y24: {=IFERROR(INDEX($K$14:$Q$44,SMALL(IF(($P$14:$P$44<$O$2),MATCH(ROW($K$14:$Q$44),ROW($K$14:$Q$44)),""),ROWS($S$14:Y24)),COLUMNS($A$1:G11)),"")}
K25: {=IFERROR(INDEX(Main[],SMALL(IF((Main[PROGRESS]<1),MATCH(ROW(Main[]),ROW(Main[])),""),ROWS(K$15:$K25)),COLUMNS($A$1:A11)),"")} | L25: {=IFERROR(INDEX(Main[],SMALL(IF((Main[PROGRESS]<1),MATCH(ROW(Main[]),ROW(Main[])),""),ROWS($K$14:L25)),COLUMNS($A$1:B12)),"")} | M25: {=IFERROR(INDEX(Main[],SMALL(IF((Main[PROGRESS]<1),MATCH(ROW(Main[]),ROW(Main[])),""),ROWS($K$14:M25)),COLUMNS($A$1:C12)),"")} | N25: {=IFERROR(INDEX(Main[],SMALL(IF((Main[PROGRESS]<1),MATCH(ROW(Main[]),ROW(Main[])),""),ROWS($K$14:N25)),COLUMNS($A$1:D12)),"")} | O25: {=IFERROR(INDEX(Main[],SMALL(IF((Main[PROGRESS]<1),MATCH(ROW(Main[]),ROW(Main[])),""),ROWS($K$14:O25)),COLUMNS($A$1:E12)),"")} | P25: {=IFERROR(INDEX(Main[],SMALL(IF((Main[PROGRESS]<1),MATCH(ROW(Main[]),ROW(Main[])),""),ROWS($K$14:P25)),COLUMNS($A$1:F12)),"")} | Q25: {=IFERROR(INDEX(Main[],SMALL(IF((Main[PROGRESS]<1),MATCH(ROW(Main[]),ROW(Main[])),""),ROWS($K$14:Q25)),COLUMNS($A$1:G12)),"")} | S25: {=IFERROR(INDEX($K$14:$Q$44,SMALL(IF(($P$14:$P$44<$O$2),MATCH(ROW($K$14:$Q$44),ROW($K$14:$Q$44)),""),ROWS(S$14:$S25)),COLUMNS($A$1:A12)),"")} | T25: {=IFERROR(INDEX($K$14:$Q$44,SMALL(IF(($P$14:$P$44<$O$2),MATCH(ROW($K$14:$Q$44),ROW($K$14:$Q$44)),""),ROWS($S$14:T25)),COLUMNS($A$1:B12)),"")} | U25: {=IFERROR(INDEX($K$14:$Q$44,SMALL(IF(($P$14:$P$44<$O$2),MATCH(ROW($K$14:$Q$44),ROW($K$14:$Q$44)),""),ROWS($S$14:U25)),COLUMNS($A$1:C12)),"")} | V25: {=IFERROR(INDEX($K$14:$Q$44,SMALL(IF(($P$14:$P$44<$O$2),MATCH(ROW($K$14:$Q$44),ROW($K$14:$Q$44)),""),ROWS($S$14:V25)),COLUMNS($A$1:D12)),"")} | W25: {=IFERROR(INDEX($K$14:$Q$44,SMALL(IF(($P$14:$P$44<$O$2),MATCH(ROW($K$14:$Q$44),ROW($K$14:$Q$44)),""),ROWS($S$14:W25)),COLUMNS($A$1:E12)),"")} | X25: {=IFERROR(INDEX($K$14:$Q$44,SMALL(IF(($P$14:$P$44<$O$2),MATCH(ROW($K$14:$Q$44),ROW($K$14:$Q$44)),""),ROWS($S$14:X25)),COLUMNS($A$1:F12)),"")} | Y25: {=IFERROR(INDEX($K$14:$Q$44,SMALL(IF(($P$14:$P$44<$O$2),MATCH(ROW($K$14:$Q$44),ROW($K$14:$Q$44)),""),ROWS($S$14:Y25)),COLUMNS($A$1:G12)),"")}
K26: {=IFERROR(INDEX(Main[],SMALL(IF((Main[PROGRESS]<1),MATCH(ROW(Main[]),ROW(Main[])),""),ROWS(K$15:$K26)),COLUMNS($A$1:A12)),"")} | L26: {=IFERROR(INDEX(Main[],SMALL(IF((Main[PROGRESS]<1),MATCH(ROW(Main[]),ROW(Main[])),""),ROWS($K$14:L26)),COLUMNS($A$1:B13)),"")} | M26: {=IFERROR(INDEX(Main[],SMALL(IF((Main[PROGRESS]<1),MATCH(ROW(Main[]),ROW(Main[])),""),ROWS($K$14:M26)),COLUMNS($A$1:C13)),"")} | N26: {=IFERROR(INDEX(Main[],SMALL(IF((Main[PROGRESS]<1),MATCH(ROW(Main[]),ROW(Main[])),""),ROWS($K$14:N26)),COLUMNS($A$1:D13)),"")} | O26: {=IFERROR(INDEX(Main[],SMALL(IF((Main[PROGRESS]<1),MATCH(ROW(Main[]),ROW(Main[])),""),ROWS($K$14:O26)),COLUMNS($A$1:E13)),"")} | P26: {=IFERROR(INDEX(Main[],SMALL(IF((Main[PROGRESS]<1),MATCH(ROW(Main[]),ROW(Main[])),""),ROWS($K$14:P26)),COLUMNS($A$1:F13)),"")} | Q26: {=IFERROR(INDEX(Main[],SMALL(IF((Main[PROGRESS]<1),MATCH(ROW(Main[]),ROW(Main[])),""),ROWS($K$14:Q26)),COLUMNS($A$1:G13)),"")} | S26: {=IFERROR(INDEX($K$14:$Q$44,SMALL(IF(($P$14:$P$44<$O$2),MATCH(ROW($K$14:$Q$44),ROW($K$14:$Q$44)),""),ROWS(S$14:$S26)),COLUMNS($A$1:A13)),"")} | T26: {=IFERROR(INDEX($K$14:$Q$44,SMALL(IF(($P$14:$P$44<$O$2),MATCH(ROW($K$14:$Q$44),ROW($K$14:$Q$44)),""),ROWS($S$14:T26)),COLUMNS($A$1:B13)),"")} | U26: {=IFERROR(INDEX($K$14:$Q$44,SMALL(IF(($P$14:$P$44<$O$2),MATCH(ROW($K$14:$Q$44),ROW($K$14:$Q$44)),""),ROWS($S$14:U26)),COLUMNS($A$1:C13)),"")} | V26: {=IFERROR(INDEX($K$14:$Q$44,SMALL(IF(($P$14:$P$44<$O$2),MATCH(ROW($K$14:$Q$44),ROW($K$14:$Q$44)),""),ROWS($S$14:V26)),COLUMNS($A$1:D13)),"")} | W26: {=IFERROR(INDEX($K$14:$Q$44,SMALL(IF(($P$14:$P$44<$O$2),MATCH(ROW($K$14:$Q$44),ROW($K$14:$Q$44)),""),ROWS($S$14:W26)),COLUMNS($A$1:E13)),"")} | X26: {=IFERROR(INDEX($K$14:$Q$44,SMALL(IF(($P$14:$P$44<$O$2),MATCH(ROW($K$14:$Q$44),ROW($K$14:$Q$44)),""),ROWS($S$14:X26)),COLUMNS($A$1:F13)),"")} | Y26: {=IFERROR(INDEX($K$14:$Q$44,SMALL(IF(($P$14:$P$44<$O$2),MATCH(ROW($K$14:$Q$44),ROW($K$14:$Q$44)),""),ROWS($S$14:Y26)),COLUMNS($A$1:G13)),"")}
K27: {=IFERROR(INDEX(Main[],SMALL(IF((Main[PROGRESS]<1),MATCH(ROW(Main[]),ROW(Main[])),""),ROWS(K$15:$K27)),COLUMNS($A$1:A13)),"")} | M27: {=IFERROR(INDEX(Main[],SMALL(IF((Main[PROGRESS]<1),MATCH(ROW(Main[]),ROW(Main[])),""),ROWS($K$14:M27)),COLUMNS($A$1:C14)),"")} | N27: {=IFERROR(INDEX(Main[],SMALL(IF((Main[PROGRESS]<1),MATCH(ROW(Main[]),ROW(Main[])),""),ROWS($K$14:N27)),COLUMNS($A$1:D14)),"")} | O27: {=IFERROR(INDEX(Main[],SMALL(IF((Main[PROGRESS]<1),MATCH(ROW(Main[]),ROW(Main[])),""),ROWS($K$14:O27)),COLUMNS($A$1:E14)),"")} | P27: {=IFERROR(INDEX(Main[],SMALL(IF((Main[PROGRESS]<1),MATCH(ROW(Main[]),ROW(Main[])),""),ROWS($K$14:P27)),COLUMNS($A$1:F14)),"")} | Q27: {=IFERROR(INDEX(Main[],SMALL(IF((Main[PROGRESS]<1),MATCH(ROW(Main[]),ROW(Main[])),""),ROWS($K$14:Q27)),COLUMNS($A$1:G14)),"")} | S27: {=IFERROR(INDEX($K$14:$Q$44,SMALL(IF(($P$14:$P$44<$O$2),MATCH(ROW($K$14:$Q$44),ROW($K$14:$Q$44)),""),ROWS(S$14:$S27)),COLUMNS($A$1:A14)),"")} | T27: {=IFERROR(INDEX($K$14:$Q$44,SMALL(IF(($P$14:$P$44<$O$2),MATCH(ROW($K$14:$Q$44),ROW($K$14:$Q$44)),""),ROWS($S$14:T27)),COLUMNS($A$1:B14)),"")} | U27: {=IFERROR(INDEX($K$14:$Q$44,SMALL(IF(($P$14:$P$44<$O$2),MATCH(ROW($K$14:$Q$44),ROW($K$14:$Q$44)),""),ROWS($S$14:U27)),COLUMNS($A$1:C14)),"")} | V27: {=IFERROR(INDEX($K$14:$Q$44,SMALL(IF(($P$14:$P$44<$O$2),MATCH(ROW($K$14:$Q$44),ROW($K$14:$Q$44)),""),ROWS($S$14:V27)),COLUMNS($A$1:D14)),"")} | W27: {=IFERROR(INDEX($K$14:$Q$44,SMALL(IF(($P$14:$P$44<$O$2),MATCH(ROW($K$14:$Q$44),ROW($K$14:$Q$44)),""),ROWS($S$14:W27)),COLUMNS($A$1:E14)),"")} | X27: {=IFERROR(INDEX($K$14:$Q$44,SMALL(IF(($P$14:$P$44<$O$2),MATCH(ROW($K$14:$Q$44),ROW($K$14:$Q$44)),""),ROWS($S$14:X27)),COLUMNS($A$1:F14)),"")} | Y27: {=IFERROR(INDEX($K$14:$Q$44,SMALL(IF(($P$14:$P$44<$O$2),MATCH(ROW($K$14:$Q$44),ROW($K$14:$Q$44)),""),ROWS($S$14:Y27)),COLUMNS($A$1:G14)),"")}
K28: {=IFERROR(INDEX(Main[],SMALL(IF((Main[PROGRESS]<1),MATCH(ROW(Main[]),ROW(Main[])),""),ROWS(K$15:$K28)),COLUMNS($A$1:A14)),"")} | L28: {=IFERROR(INDEX(Main[],SMALL(IF((Main[PROGRESS]<1),MATCH(ROW(Main[]),ROW(Main[])),""),ROWS($K$14:L28)),COLUMNS($A$1:B15)),"")} | M28: {=IFERROR(INDEX(Main[],SMALL(IF((Main[PROGRESS]<1),MATCH(ROW(Main[]),ROW(Main[])),""),ROWS($K$14:M28)),COLUMNS($A$1:C15)),"")} | N28: {=IFERROR(INDEX(Main[],SMALL(IF((Main[PROGRESS]<1),MATCH(ROW(Main[]),ROW(Main[])),""),ROWS($K$14:N28)),COLUMNS($A$1:D15)),"")} | O28: {=IFERROR(INDEX(Main[],SMALL(IF((Main[PROGRESS]<1),MATCH(ROW(Main[]),ROW(Main[])),""),ROWS($K$14:O28)),COLUMNS($A$1:E15)),"")} | P28: {=IFERROR(INDEX(Main[],SMALL(IF((Main[PROGRESS]<1),MATCH(ROW(Main[]),ROW(Main[])),""),ROWS($K$14:P28)),COLUMNS($A$1:F15)),"")} | Q28: {=IFERROR(INDEX(Main[],SMALL(IF((Main[PROGRESS]<1),MATCH(ROW(Main[]),ROW(Main[])),""),ROWS($K$14:Q28)),COLUMNS($A$1:G15)),"")}
K29: {=IFERROR(INDEX(Main[],SMALL(IF((Main[PROGRESS]<1),MATCH(ROW(Main[]),ROW(Main[])),""),ROWS(K$15:$K29)),COLUMNS($A$1:A15)),"")} | L29: {=IFERROR(INDEX(Main[],SMALL(IF((Main[PROGRESS]<1),MATCH(ROW(Main[]),ROW(Main[])),""),ROWS($K$14:L29)),COLUMNS($A$1:B16)),"")} | M29: {=IFERROR(INDEX(Main[],SMALL(IF((Main[PROGRESS]<1),MATCH(ROW(Main[]),ROW(Main[])),""),ROWS($K$14:M29)),COLUMNS($A$1:C16)),"")} | N29: {=IFERROR(INDEX(Main[],SMALL(IF((Main[PROGRESS]<1),MATCH(ROW(Main[]),ROW(Main[])),""),ROWS($K$14:N29)),COLUMNS($A$1:D16)),"")} | O29: {=IFERROR(INDEX(Main[],SMALL(IF((Main[PROGRESS]<1),MATCH(ROW(Main[]),ROW(Main[])),""),ROWS($K$14:O29)),COLUMNS($A$1:E16)),"")} | P29: {=IFERROR(INDEX(Main[],SMALL(IF((Main[PROGRESS]<1),MATCH(ROW(Main[]),ROW(Main[])),""),ROWS($K$14:P29)),COLUMNS($A$1:F16)),"")} | Q29: {=IFERROR(INDEX(Main[],SMALL(IF((Main[PROGRESS]<1),MATCH(ROW(Main[]),ROW(Main[])),""),ROWS($K$14:Q29)),COLUMNS($A$1:G16)),"")}
K30: {=IFERROR(INDEX(Main[],SMALL(IF((Main[PROGRESS]<1),MATCH(ROW(Main[]),ROW(Main[])),""),ROWS(K$15:$K30)),COLUMNS($A$1:A16)),"")} | L30: {=IFERROR(INDEX(Main[],SMALL(IF((Main[PROGRESS]<1),MATCH(ROW(Main[]),ROW(Main[])),""),ROWS($K$14:L30)),COLUMNS($A$1:B17)),"")} | M30: {=IFERROR(INDEX(Main[],SMALL(IF((Main[PROGRESS]<1),MATCH(ROW(Main[]),ROW(Main[])),""),ROWS($K$14:M30)),COLUMNS($A$1:C17)),"")} | N30: {=IFERROR(INDEX(Main[],SMALL(IF((Main[PROGRESS]<1),MATCH(ROW(Main[]),ROW(Main[])),""),ROWS($K$14:N30)),COLUMNS($A$1:D17)),"")} | O30: {=IFERROR(INDEX(Main[],SMALL(IF((Main[PROGRESS]<1),MATCH(ROW(Main[]),ROW(Main[])),""),ROWS($K$14:O30)),COLUMNS($A$1:E17)),"")} | P30: {=IFERROR(INDEX(Main[],SMALL(IF((Main[PROGRESS]<1),MATCH(ROW(Main[]),ROW(Main[])),""),ROWS($K$14:P30)),COLUMNS($A$1:F17)),"")} | Q30: {=IFERROR(INDEX(Main[],SMALL(IF((Main[PROGRESS]<1),MATCH(ROW(Main[]),ROW(Main[])),""),ROWS($K$14:Q30)),COLUMNS($A$1:G17)),"")}
K31: {=IFERROR(INDEX(Main[],SMALL(IF((Main[PROGRESS]<1),MATCH(ROW(Main[]),ROW(Main[])),""),ROWS(K$15:$K31)),COLUMNS($A$1:A17)),"")} | L31: {=IFERROR(INDEX(Main[],SMALL(IF((Main[PROGRESS]<1),MATCH(ROW(Main[]),ROW(Main[])),""),ROWS($K$14:L31)),COLUMNS($A$1:B18)),"")} | M31: {=IFERROR(INDEX(Main[],SMALL(IF((Main[PROGRESS]<1),MATCH(ROW(Main[]),ROW(Main[])),""),ROWS($K$14:M31)),COLUMNS($A$1:C18)),"")} | N31: {=IFERROR(INDEX(Main[],SMALL(IF((Main[PROGRESS]<1),MATCH(ROW(Main[]),ROW(Main[])),""),ROWS($K$14:N31)),COLUMNS($A$1:D18)),"")} | O31: {=IFERROR(INDEX(Main[],SMALL(IF((Main[PROGRESS]<1),MATCH(ROW(Main[]),ROW(Main[])),""),ROWS($K$14:O31)),COLUMNS($A$1:E18)),"")} | P31: {=IFERROR(INDEX(Main[],SMALL(IF((Main[PROGRESS]<1),MATCH(ROW(Main[]),ROW(Main[])),""),ROWS($K$14:P31)),COLUMNS($A$1:F18)),"")} | Q31: {=IFERROR(INDEX(Main[],SMALL(IF((Main[PROGRESS]<1),MATCH(ROW(Main[]),ROW(Main[])),""),ROWS($K$14:Q31)),COLUMNS($A$1:G18)),"")}
K32: {=IFERROR(INDEX(Main[],SMALL(IF((Main[PROGRESS]<1),MATCH(ROW(Main[]),ROW(Main[])),""),ROWS(K$15:$K32)),COLUMNS($A$1:A18)),"")} | L32: {=IFERROR(INDEX(Main[],SMALL(IF((Main[PROGRESS]<1),MATCH(ROW(Main[]),ROW(Main[])),""),ROWS($K$14:L32)),COLUMNS($A$1:B19)),"")} | M32: {=IFERROR(INDEX(Main[],SMALL(IF((Main[PROGRESS]<1),MATCH(ROW(Main[]),ROW(Main[])),""),ROWS($K$14:M32)),COLUMNS($A$1:C19)),"")} | N32: {=IFERROR(INDEX(Main[],SMALL(IF((Main[PROGRESS]<1),MATCH(ROW(Main[]),ROW(Main[])),""),ROWS($K$14:N32)),COLUMNS($A$1:D19)),"")} | O32: {=IFERROR(INDEX(Main[],SMALL(IF((Main[PROGRESS]<1),MATCH(ROW(Main[]),ROW(Main[])),""),ROWS($K$14:O32)),COLUMNS($A$1:E19)),"")} | P32: {=IFERROR(INDEX(Main[],SMALL(IF((Main[PROGRESS]<1),MATCH(ROW(Main[]),ROW(Main[])),""),ROWS($K$14:P32)),COLUMNS($A$1:F19)),"")} | Q32: {=IFERROR(INDEX(Main[],SMALL(IF((Main[PROGRESS]<1),MATCH(ROW(Main[]),ROW(Main[])),""),ROWS($K$14:Q32)),COLUMNS($A$1:G19)),"")}
K33: {=IFERROR(INDEX(Main[],SMALL(IF((Main[PROGRESS]<1),MATCH(ROW(Main[]),ROW(Main[])),""),ROWS(K$15:$K33)),COLUMNS($A$1:A19)),"")} | L33: {=IFERROR(INDEX(Main[],SMALL(IF((Main[PROGRESS]<1),MATCH(ROW(Main[]),ROW(Main[])),""),ROWS($K$14:L33)),COLUMNS($A$1:B20)),"")} | M33: {=IFERROR(INDEX(Main[],SMALL(IF((Main[PROGRESS]<1),MATCH(ROW(Main[]),ROW(Main[])),""),ROWS($K$14:M33)),COLUMNS($A$1:C20)),"")} | N33: {=IFERROR(INDEX(Main[],SMALL(IF((Main[PROGRESS]<1),MATCH(ROW(Main[]),ROW(Main[])),""),ROWS($K$14:N33)),COLUMNS($A$1:D20)),"")} | O33: {=IFERROR(INDEX(Main[],SMALL(IF((Main[PROGRESS]<1),MATCH(ROW(Main[]),ROW(Main[])),""),ROWS($K$14:O33)),COLUMNS($A$1:E20)),"")} | P33: {=IFERROR(INDEX(Main[],SMALL(IF((Main[PROGRESS]<1),MATCH(ROW(Main[]),ROW(Main[])),""),ROWS($K$14:P33)),COLUMNS($A$1:F20)),"")} | Q33: {=IFERROR(INDEX(Main[],SMALL(IF((Main[PROGRESS]<1),MATCH(ROW(Main[]),ROW(Main[])),""),ROWS($K$14:Q33)),COLUMNS($A$1:G20)),"")}
K34: {=IFERROR(INDEX(Main[],SMALL(IF((Main[PROGRESS]<1),MATCH(ROW(Main[]),ROW(Main[])),""),ROWS(K$15:$K34)),COLUMNS($A$1:A20)),"")} | L34: {=IFERROR(INDEX(Main[],SMALL(IF((Main[PROGRESS]<1),MATCH(ROW(Main[]),ROW(Main[])),""),ROWS($K$14:L34)),COLUMNS($A$1:B21)),"")} | M34: {=IFERROR(INDEX(Main[],SMALL(IF((Main[PROGRESS]<1),MATCH(ROW(Main[]),ROW(Main[])),""),ROWS($K$14:M34)),COLUMNS($A$1:C21)),"")} | N34: {=IFERROR(INDEX(Main[],SMALL(IF((Main[PROGRESS]<1),MATCH(ROW(Main[]),ROW(Main[])),""),ROWS($K$14:N34)),COLUMNS($A$1:D21)),"")} | O34: {=IFERROR(INDEX(Main[],SMALL(IF((Main[PROGRESS]<1),MATCH(ROW(Main[]),ROW(Main[])),""),ROWS($K$14:O34)),COLUMNS($A$1:E21)),"")} | P34: {=IFERROR(INDEX(Main[],SMALL(IF((Main[PROGRESS]<1),MATCH(ROW(Main[]),ROW(Main[])),""),ROWS($K$14:P34)),COLUMNS($A$1:F21)),"")} | Q34: {=IFERROR(INDEX(Main[],SMALL(IF((Main[PROGRESS]<1),MATCH(ROW(Main[]),ROW(Main[])),""),ROWS($K$14:Q34)),COLUMNS($A$1:G21)),"")}
K35: {=IFERROR(INDEX(Main[],SMALL(IF((Main[PROGRESS]<1),MATCH(ROW(Main[]),ROW(Main[])),""),ROWS(K$15:$K35)),COLUMNS($A$1:A21)),"")} | L35: {=IFERROR(INDEX(Main[],SMALL(IF((Main[PROGRESS]<1),MATCH(ROW(Main[]),ROW(Main[])),""),ROWS($K$14:L35)),COLUMNS($A$1:B22)),"")} | M35: {=IFERROR(INDEX(Main[],SMALL(IF((Main[PROGRESS]<1),MATCH(ROW(Main[]),ROW(Main[])),""),ROWS($K$14:M35)),COLUMNS($A$1:C22)),"")} | N35: {=IFERROR(INDEX(Main[],SMALL(IF((Main[PROGRESS]<1),MATCH(ROW(Main[]),ROW(Main[])),""),ROWS($K$14:N35)),COLUMNS($A$1:D22)),"")} | O35: {=IFERROR(INDEX(Main[],SMALL(IF((Main[PROGRESS]<1),MATCH(ROW(Main[]),ROW(Main[])),""),ROWS($K$14:O35)),COLUMNS($A$1:E22)),"")} | P35: {=IFERROR(INDEX(Main[],SMALL(IF((Main[PROGRESS]<1),MATCH(ROW(Main[]),ROW(Main[])),""),ROWS($K$14:P35)),COLUMNS($A$1:F22)),"")} | Q35: {=IFERROR(INDEX(Main[],SMALL(IF((Main[PROGRESS]<1),MATCH(ROW(Main[]),ROW(Main[])),""),ROWS($K$14:Q35)),COLUMNS($A$1:G22)),"")}
K36: {=IFERROR(INDEX(Main[],SMALL(IF((Main[PROGRESS]<1),MATCH(ROW(Main[]),ROW(Main[])),""),ROWS(K$15:$K36)),COLUMNS($A$1:A22)),"")} | L36: {=IFERROR(INDEX(Main[],SMALL(IF((Main[PROGRESS]<1),MATCH(ROW(Main[]),ROW(Main[])),""),ROWS($K$14:L36)),COLUMNS($A$1:B23)),"")} | M36: {=IFERROR(INDEX(Main[],SMALL(IF((Main[PROGRESS]<1),MATCH(ROW(Main[]),ROW(Main[])),""),ROWS($K$14:M36)),COLUMNS($A$1:C23)),"")} | N36: {=IFERROR(INDEX(Main[],SMALL(IF((Main[PROGRESS]<1),MATCH(ROW(Main[]),ROW(Main[])),""),ROWS($K$14:N36)),COLUMNS($A$1:D23)),"")} | O36: {=IFERROR(INDEX(Main[],SMALL(IF((Main[PROGRESS]<1),MATCH(ROW(Main[]),ROW(Main[])),""),ROWS($K$14:O36)),COLUMNS($A$1:E23)),"")} | P36: {=IFERROR(INDEX(Main[],SMALL(IF((Main[PROGRESS]<1),MATCH(ROW(Main[]),ROW(Main[])),""),ROWS($K$14:P36)),COLUMNS($A$1:F23)),"")} | Q36: {=IFERROR(INDEX(Main[],SMALL(IF((Main[PROGRESS]<1),MATCH(ROW(Main[]),ROW(Main[])),""),ROWS($K$14:Q36)),COLUMNS($A$1:G23)),"")}
K37: {=IFERROR(INDEX(Main[],SMALL(IF((Main[PROGRESS]<1),MATCH(ROW(Main[]),ROW(Main[])),""),ROWS(K$15:$K37)),COLUMNS($A$1:A23)),"")} | L37: {=IFERROR(INDEX(Main[],SMALL(IF((Main[PROGRESS]<1),MATCH(ROW(Main[]),ROW(Main[])),""),ROWS($K$14:L37)),COLUMNS($A$1:B24)),"")} | M37: {=IFERROR(INDEX(Main[],SMALL(IF((Main[PROGRESS]<1),MATCH(ROW(Main[]),ROW(Main[])),""),ROWS($K$14:M37)),COLUMNS($A$1:C24)),"")} | N37: {=IFERROR(INDEX(Main[],SMALL(IF((Main[PROGRESS]<1),MATCH(ROW(Main[]),ROW(Main[])),""),ROWS($K$14:N37)),COLUMNS($A$1:D24)),"")} | O37: {=IFERROR(INDEX(Main[],SMALL(IF((Main[PROGRESS]<1),MATCH(ROW(Main[]),ROW(Main[])),""),ROWS($K$14:O37)),COLUMNS($A$1:E24)),"")} | P37: {=IFERROR(INDEX(Main[],SMALL(IF((Main[PROGRESS]<1),MATCH(ROW(Main[]),ROW(Main[])),""),ROWS($K$14:P37)),COLUMNS($A$1:F24)),"")} | Q37: {=IFERROR(INDEX(Main[],SMALL(IF((Main[PROGRESS]<1),MATCH(ROW(Main[]),ROW(Main[])),""),ROWS($K$14:Q37)),COLUMNS($A$1:G24)),"")}
K38: {=IFERROR(INDEX(Main[],SMALL(IF((Main[PROGRESS]<1),MATCH(ROW(Main[]),ROW(Main[])),""),ROWS(K$15:$K38)),COLUMNS($A$1:A24)),"")} | L38: {=IFERROR(INDEX(Main[],SMALL(IF((Main[PROGRESS]<1),MATCH(ROW(Main[]),ROW(Main[])),""),ROWS($K$14:L38)),COLUMNS($A$1:B25)),"")} | M38: {=IFERROR(INDEX(Main[],SMALL(IF((Main[PROGRESS]<1),MATCH(ROW(Main[]),ROW(Main[])),""),ROWS($K$14:M38)),COLUMNS($A$1:C25)),"")} | N38: {=IFERROR(INDEX(Main[],SMALL(IF((Main[PROGRESS]<1),MATCH(ROW(Main[]),ROW(Main[])),""),ROWS($K$14:N38)),COLUMNS($A$1:D25)),"")} | O38: {=IFERROR(INDEX(Main[],SMALL(IF((Main[PROGRESS]<1),MATCH(ROW(Main[]),ROW(Main[])),""),ROWS($K$14:O38)),COLUMNS($A$1:E25)),"")} | P38: {=IFERROR(INDEX(Main[],SMALL(IF((Main[PROGRESS]<1),MATCH(ROW(Main[]),ROW(Main[])),""),ROWS($K$14:P38)),COLUMNS($A$1:F25)),"")} | Q38: {=IFERROR(INDEX(Main[],SMALL(IF((Main[PROGRESS]<1),MATCH(ROW(Main[]),ROW(Main[])),""),ROWS($K$14:Q38)),COLUMNS($A$1:G25)),"")}
K39: {=IFERROR(INDEX(Main[],SMALL(IF((Main[PROGRESS]<1),MATCH(ROW(Main[]),ROW(Main[])),""),ROWS(K$15:$K39)),COLUMNS($A$1:A25)),"")} | L39: {=IFERROR(INDEX(Main[],SMALL(IF((Main[PROGRESS]<1),MATCH(ROW(Main[]),ROW(Main[])),""),ROWS($K$14:L39)),COLUMNS($A$1:B26)),"")} | M39: {=IFERROR(INDEX(Main[],SMALL(IF((Main[PROGRESS]<1),MATCH(ROW(Main[]),ROW(Main[])),""),ROWS($K$14:M39)),COLUMNS($A$1:C26)),"")} | N39: {=IFERROR(INDEX(Main[],SMALL(IF((Main[PROGRESS]<1),MATCH(ROW(Main[]),ROW(Main[])),""),ROWS($K$14:N39)),COLUMNS($A$1:D26)),"")} | O39: {=IFERROR(INDEX(Main[],SMALL(IF((Main[PROGRESS]<1),MATCH(ROW(Main[]),ROW(Main[])),""),ROWS($K$14:O39)),COLUMNS($A$1:E26)),"")} | P39: {=IFERROR(INDEX(Main[],SMALL(IF((Main[PROGRESS]<1),MATCH(ROW(Main[]),ROW(Main[])),""),ROWS($K$14:P39)),COLUMNS($A$1:F26)),"")} | Q39: {=IFERROR(INDEX(Main[],SMALL(IF((Main[PROGRESS]<1),MATCH(ROW(Main[]),ROW(Main[])),""),ROWS($K$14:Q39)),COLUMNS($A$1:G26)),"")}
... K44: {=IFERROR(INDEX(Main[],SMALL(IF((Main[PROGRESS]<1),MATCH(ROW(Main[]),ROW(Main[])),""),ROWS(K$15:$K44)),COLUMNS($A$1:A30)),"")} | L44: {=IFERROR(INDEX(Main[],SMALL(IF((Main[PROGRESS]<1),MATCH(ROW(Main[]),ROW(Main[])),""),ROWS($K$14:L44)),COLUMNS($A$1:B31)),"")} | M44: {=IFERROR(INDEX(Main[],SMALL(IF((Main[PROGRESS]<1),MATCH(ROW(Main[]),ROW(Main[])),""),ROWS($K$14:M44)),COLUMNS($A$1:C31)),"")} | N44: {=IFERROR(INDEX(Main[],SMALL(IF((Main[PROGRESS]<1),MATCH(ROW(Main[]),ROW(Main[])),""),ROWS($K$14:N44)),COLUMNS($A$1:D31)),"")} | O44: {=IFERROR(INDEX(Main[],SMALL(IF((Main[PROGRESS]<1),MATCH(ROW(Main[]),ROW(Main[])),""),ROWS($K$14:O44)),COLUMNS($A$1:E31)),"")} | P44: {=IFERROR(INDEX(Main[],SMALL(IF((Main[PROGRESS]<1),MATCH(ROW(Main[]),ROW(Main[])),""),ROWS($K$14:P44)),COLUMNS($A$1:F31)),"")} | Q44: {=IFERROR(INDEX(Main[],SMALL(IF((Main[PROGRESS]<1),MATCH(ROW(Main[]),ROW(Main[])),""),ROWS($K$14:Q44)),COLUMNS($A$1:G31)),"")}
...

Sheet Calculations
B3: Total projects: | C3: =COUNTA(Projects[Projects]) -> 1 | J3: Total days scope: | K3: =MAX(Main[END DATE])-MIN(Main[START DATE]) -> 31
B5: Total taskss: | C5: =C11 -> 14 | J5: Not started | K5: =COUNTIF(Main[PROGRESS],"=0") -> 0
J6: In Progress | K6: =COUNTIFS(Main[PROGRESS],">0", Main[PROGRESS],"<1") -> 7
J7: Completed | K7: =COUNTIF(Main[PROGRESS],"=1") -> 14
B10: Projects | C10: Tasks | D10: Start | E10: End | F10: Days Required | G10: Progress | H10: Remaining | J10: Projects | K10: Tasks | L10: Days Engaged | M10: Progress | N10: Remaining | O10: Max man-days
B11: All Projects | C11: =COUNTA(Main[TASK]) -> 14 | D11: =MIN(Main[START DATE]) -> 45717 | E11: =MAX(Main[END DATE]) -> 45748 | F11: =+K3 -> 31 | G11: =AVERAGE(Main[PROGRESS]) -> 0.83333333 | H11: =IFERROR(1-G11,"") -> 0.16666667 | J11: All Resources | K11: =COUNTA(Main[TASK]) -> 14 | L11: =+K3 -> 31 | M11: =AVERAGE(Main[PROGRESS]) -> 0.83333333 | N11: =IFERROR(1-M11,"") -> 0.16666667
B12: =_xlfn.IFS(Data!K2<>0, Data!K2,Data!K2=0, #N/A) -> BASE DE CONNAISSANCE IA OP | C12: =COUNTIF(Main[PROJECT],B12) -> 21 | D12: {=MIN(IF(Main[PROJECT]=B12,Main[START DATE]))} -> 45717 | E12: {=MAX(IF(Main[PROJECT]=B12, Main[END DATE]))} -> 45748 | F12: =E12-D12 -> 31 | G12: =AVERAGEIF(Main[PROJECT], B12, Main[PROGRESS]) -> 0.83333333 | H12: =IFERROR(1-G12,"") -> 0.16666667 | J12: =_xlfn.IFS(Data!M2<>0, Data!M2,Data!M2=0, #N/A) -> MCCI | K12: =COUNTIF(Main[ASIGNEE],J12) -> 2 | L12: =SUMIF(Main[ASIGNEE], J12, Main[DAYS REQUIRED]) -> 15 | M12: =AVERAGEIF(Main[ASIGNEE], J12, Main[PROGRESS]) -> 1 | N12: =IFERROR(1-M12,"") -> 0 | O12: =IF(K12>0, $K$3, "") -> 31
B13: =_xlfn.IFS(Data!K3<>0, Data!K3,Data!K3=0, #N/A) -> #N/A | C13: =COUNTIF(Main[PROJECT],B13) -> 0 | D13: {=MIN(IF(Main[PROJECT]=B13,Main[START DATE]))} -> #N/A | E13: {=MAX(IF(Main[PROJECT]=B13, Main[END DATE]))} -> #N/A | F13: =SUMIF(Main[PROJECT], B13, Main[DAYS REQUIRED]) -> 0 | G13: =AVERAGEIF(Main[PROJECT], B13, Main[PROGRESS]) -> #DIV/0! | H13: =IFERROR(1-G13,"") | J13: =_xlfn.IFS(Data!M3<>0, Data!M3,Data!M3=0, #N/A) -> MCAM | K13: =COUNTIF(Main[ASIGNEE],J13) -> 2 | L13: =SUMIF(Main[ASIGNEE], J13, Main[DAYS REQUIRED]) -> 15 | M13: =AVERAGEIF(Main[ASIGNEE], J13, Main[PROGRESS]) -> 1 | N13: =IFERROR(1-M13,"") -> 0 | O13: =IF(K13>0, $K$3, "") -> 31
B14: =_xlfn.IFS(Data!K5<>0, Data!K5,Data!K5=0, #N/A) -> #N/A | C14: =COUNTIF(Main[PROJECT],B14) -> 0 | D14: {=MIN(IF(Main[PROJECT]=B14,Main[START DATE]))} -> #N/A | E14: {=MAX(IF(Main[PROJECT]=B14, Main[END DATE]))} -> #N/A | F14: =SUMIF(Main[PROJECT], B14, Main[DAYS REQUIRED]) -> 0 | G14: =AVERAGEIF(Main[PROJECT], B14, Main[PROGRESS]) -> #DIV/0! | H14: =IFERROR(1-G14,"") | J14: =_xlfn.IFS(Data!M4<>0, Data!M4,Data!M4=0, #N/A) -> MCGB | K14: =COUNTIF(Main[ASIGNEE],J14) -> 2 | L14: =SUMIF(Main[ASIGNEE], J14, Main[DAYS REQUIRED]) -> 15 | M14: =AVERAGEIF(Main[ASIGNEE], J14, Main[PROGRESS]) -> 1 | N14: =IFERROR(1-M14,"") -> 0 | O14: =IF(K14>0, $K$3, "") -> 31
B15: =_xlfn.IFS(Data!K6<>0, Data!K6,Data!K6=0, #N/A) -> #N/A | C15: =COUNTIF(Main[PROJECT],B15) -> 0 | D15: {=MIN(IF(Main[PROJECT]=B15,Main[START DATE]))} -> #N/A | E15: {=MAX(IF(Main[PROJECT]=B15, Main[END DATE]))} -> #N/A | F15: =SUMIF(Main[PROJECT], B15, Main[DAYS REQUIRED]) -> 0 | G15: =AVERAGEIF(Main[PROJECT], B15, Main[PROGRESS]) -> #DIV/0! | H15: =IFERROR(1-G15,"") | J15: =_xlfn.IFS(Data!M5<>0, Data!M5,Data!M5=0, #N/A) -> MCGC | K15: =COUNTIF(Main[ASIGNEE],J15) -> 2 | L15: =SUMIF(Main[ASIGNEE], J15, Main[DAYS REQUIRED]) -> 15 | M15: =AVERAGEIF(Main[ASIGNEE], J15, Main[PROGRESS]) -> 1 | N15: =IFERROR(1-M15,"") -> 0 | O15: =IF(K15>0, $K$3, "") -> 31 | Q15: GRAPHE
B16: =_xlfn.IFS(Data!K7<>0, Data!K7,Data!K7=0, #N/A) -> #N/A | C16: =COUNTIF(Main[PROJECT],B16) -> 0 | D16: {=MIN(IF(Main[PROJECT]=B16,Main[START DATE]))} -> #N/A | E16: {=MAX(IF(Main[PROJECT]=B16, Main[END DATE]))} -> #N/A | F16: =SUMIF(Main[PROJECT], B16, Main[DAYS REQUIRED]) -> 0 | G16: =AVERAGEIF(Main[PROJECT], B16, Main[PROGRESS]) -> #DIV/0! | H16: =IFERROR(1-G16,"") | J16: =_xlfn.IFS(Data!M6<>0, Data!M6,Data!M6=0, #N/A) -> MTN B | K16: =COUNTIF(Main[ASIGNEE],J16) -> 2 | L16: =SUMIF(Main[ASIGNEE], J16, Main[DAYS REQUIRED]) -> 15 | M16: =AVERAGEIF(Main[ASIGNEE], J16, Main[PROGRESS]) -> 1 | N16: =IFERROR(1-M16,"") -> 0 | O16: =IF(K16>0, $K$3, "") -> 31
B17: =_xlfn.IFS(Data!K8<>0, Data!K8,Data!K8=0, #N/A) -> #N/A | C17: =COUNTIF(Main[PROJECT],B17) -> 0 | D17: {=MIN(IF(Main[PROJECT]=B17,Main[START DATE]))} -> #N/A | E17: {=MAX(IF(Main[PROJECT]=B17, Main[END DATE]))} -> #N/A | F17: =SUMIF(Main[PROJECT], B17, Main[DAYS REQUIRED]) -> 0 | G17: =AVERAGEIF(Main[PROJECT], B17, Main[PROGRESS]) -> #DIV/0! | H17: =IFERROR(1-G17,"") | J17: =_xlfn.IFS(Data!M7<>0, Data!M7,Data!M7=0, #N/A) -> CELTIISB | K17: =COUNTIF(Main[ASIGNEE],J17) -> 2 | L17: =SUMIF(Main[ASIGNEE], J17, Main[DAYS REQUIRED]) -> 15 | M17: =AVERAGEIF(Main[ASIGNEE], J17, Main[PROGRESS]) -> 1 | N17: =IFERROR(1-M17,"") -> 0 | O17: =IF(K17>0, $K$3, "") -> 31
B18: =_xlfn.IFS(Data!K9<>0, Data!K9,Data!K9=0, #N/A) -> #N/A | C18: =COUNTIF(Main[PROJECT],B18) -> 0 | D18: {=MIN(IF(Main[PROJECT]=B18,Main[START DATE]))} -> #N/A | E18: {=MAX(IF(Main[PROJECT]=B18, Main[END DATE]))} -> #N/A | F18: =SUMIF(Main[PROJECT], B18, Main[DAYS REQUIRED]) -> 0 | G18: =AVERAGEIF(Main[PROJECT], B18, Main[PROGRESS]) -> #DIV/0! | H18: =IFERROR(1-G18,"") | J18: =_xlfn.IFS(Data!M8<>0, Data!M8,Data!M8=0, #N/A) -> OWNER | K18: =COUNTIF(Main[ASIGNEE],J18) -> 2 | L18: =SUMIF(Main[ASIGNEE], J18, Main[DAYS REQUIRED]) -> 2 | M18: =AVERAGEIF(Main[ASIGNEE], J18, Main[PROGRESS]) -> 1 | N18: =IFERROR(1-M18,"") -> 0 | O18: =IF(K18>0, $K$3, "") -> 31
B19: =_xlfn.IFS(Data!K10<>0, Data!K10,Data!K10=0, #N/A) -> #N/A | C19: =COUNTIF(Main[PROJECT],B19) -> 0 | D19: {=MIN(IF(Main[PROJECT]=B19,Main[START DATE]))} -> #N/A | E19: {=MAX(IF(Main[PROJECT]=B19, Main[END DATE]))} -> #N/A | F19: =SUMIF(Main[PROJECT], B19, Main[DAYS REQUIRED]) -> 0 | G19: =AVERAGEIF(Main[PROJECT], B19, Main[PROGRESS]) -> #DIV/0! | H19: =IFERROR(1-G19,"") | J19: =_xlfn.IFS(Data!M9<>0, Data!M9,Data!M9=0, #N/A) -> DEV | K19: =COUNTIF(Main[ASIGNEE],J19) -> 7 | L19: =SUMIF(Main[ASIGNEE], J19, Main[DAYS REQUIRED]) -> 20 | M19: =AVERAGEIF(Main[ASIGNEE], J19, Main[PROGRESS]) -> 0.5 | N19: =IFERROR(1-M19,"") -> 0.5 | O19: =IF(K19>0, $K$3, "") -> 31
B20: =_xlfn.IFS(Data!K11<>0, Data!K11,Data!K11=0, #N/A) -> #N/A | C20: =COUNTIF(Main[PROJECT],B20) -> 0 | D20: {=MIN(IF(Main[PROJECT]=B20,Main[START DATE]))} -> #N/A | E20: {=MAX(IF(Main[PROJECT]=B20, Main[END DATE]))} -> #N/A | F20: =SUMIF(Main[PROJECT], B20, Main[DAYS REQUIRED]) -> 0 | G20: =AVERAGEIF(Main[PROJECT], B20, Main[PROGRESS]) -> #DIV/0! | H20: =IFERROR(1-G20,"") | J20: =_xlfn.IFS(Data!M10<>0, Data!M10,Data!M10=0, #N/A) -> #N/A | K20: =COUNTIF(Main[ASIGNEE],J20) -> 0 | L20: =SUMIF(Main[ASIGNEE], J20, Main[DAYS REQUIRED]) -> 0 | M20: =AVERAGEIF(Main[ASIGNEE], J20, Main[PROGRESS]) -> #DIV/0! | N20: =IFERROR(1-M20,"") | O20: =IF(K20>0, $K$3, "")
C21: =COUNTIF(Main[PROJECT],B21) -> 0 | D21: {=MIN(IF(Main[PROJECT]=B21,Main[START DATE]))} -> 0 | E21: {=MAX(IF(Main[PROJECT]=B21, Main[END DATE]))} -> 0 | F21: =SUMIF(Main[PROJECT], B21, Main[DAYS REQUIRED]) -> 0 | G21: =AVERAGEIF(Main[PROJECT], B21, Main[PROGRESS]) -> #DIV/0! | H21: =IFERROR(1-G21,"") | J21: =_xlfn.IFS(Data!M11<>0, Data!M11,Data!M11=0, #N/A) -> #N/A | K21: =COUNTIF(Main[ASIGNEE],J21) -> 0 | L21: =SUMIF(Main[ASIGNEE], J21, Main[DAYS REQUIRED]) -> 0 | M21: =AVERAGEIF(Main[ASIGNEE], J21, Main[PROGRESS]) -> #DIV/0! | N21: =IFERROR(1-M21,"") | O21: =IF(K21>0, $K$3, "")
J25: Projects | K25: Tasks | L25: Days Engaged | M25: Progress | N25: Remaining | O25: Max man-days
J26: All Resources | K26: =COUNTA(Main[TASK]) -> 14 | L26: =SUM(Main[DAYS REQUIRED]) -> 112 | M26: =AVERAGE(Main[PROGRESS]) -> 0.83333333 | N26: =IFERROR(1-M26,"") -> 0.16666667 | O26: =COUNTIF(K27:K36, ">0")*$K$3 -> 248
J27: =_xlfn.IFS(Data!M2<>0, Data!M2,Data!M2=0, #N/A) -> MCCI | K27: =COUNTIF(Main[ASIGNEE],J27) -> 2 | L27: =SUMIF(Main[ASIGNEE], J27, Main[DAYS REQUIRED]) -> 15 | M27: =AVERAGEIF(Main[ASIGNEE], J27, Main[PROGRESS]) -> 1 | N27: =IFERROR(1-M27,"") -> 0 | O27: =IF(K27>0, $K$3, "") -> 31
J28: =_xlfn.IFS(Data!M3<>0, Data!M3,Data!M3=0, #N/A) -> MCAM | K28: =COUNTIF(Main[ASIGNEE],J28) -> 2 | L28: =SUMIF(Main[ASIGNEE], J28, Main[DAYS REQUIRED]) -> 15 | M28: =AVERAGEIF(Main[ASIGNEE], J28, Main[PROGRESS]) -> 1 | N28: =IFERROR(1-M28,"") -> 0 | O28: =IF(K28>0, $K$3, "") -> 31
J29: =_xlfn.IFS(Data!M4<>0, Data!M4,Data!M4=0, #N/A) -> MCGB | K29: =COUNTIF(Main[ASIGNEE],J29) -> 2 | L29: =SUMIF(Main[ASIGNEE], J29, Main[DAYS REQUIRED]) -> 15 | M29: =AVERAGEIF(Main[ASIGNEE], J29, Main[PROGRESS]) -> 1 | N29: =IFERROR(1-M29,"") -> 0 | O29: =IF(K29>0, $K$3, "") -> 31
J30: =_xlfn.IFS(Data!M5<>0, Data!M5,Data!M5=0, #N/A) -> MCGC | K30: =COUNTIF(Main[ASIGNEE],J30) -> 2 | L30: =SUMIF(Main[ASIGNEE], J30, Main[DAYS REQUIRED]) -> 15 | M30: =AVERAGEIF(Main[ASIGNEE], J30, Main[PROGRESS]) -> 1 | N30: =IFERROR(1-M30,"") -> 0 | O30: =IF(K30>0, $K$3, "") -> 31
J31: =_xlfn.IFS(Data!M6<>0, Data!M6,Data!M6=0, #N/A) -> MTN B | K31: =COUNTIF(Main[ASIGNEE],J31) -> 2 | L31: =SUMIF(Main[ASIGNEE], J31, Main[DAYS REQUIRED]) -> 15 | M31: =AVERAGEIF(Main[ASIGNEE], J31, Main[PROGRESS]) -> 1 | N31: =IFERROR(1-M31,"") -> 0 | O31: =IF(K31>0, $K$3, "") -> 31
J32: =_xlfn.IFS(Data!M7<>0, Data!M7,Data!M7=0, #N/A) -> CELTIISB | K32: =COUNTIF(Main[ASIGNEE],J32) -> 2 | L32: =SUMIF(Main[ASIGNEE], J32, Main[DAYS REQUIRED]) -> 15 | M32: =AVERAGEIF(Main[ASIGNEE], J32, Main[PROGRESS]) -> 1 | N32: =IFERROR(1-M32,"") -> 0 | O32: =IF(K32>0, $K$3, "") -> 31
J33: =_xlfn.IFS(Data!M8<>0, Data!M8,Data!M8=0, #N/A) -> OWNER | K33: =COUNTIF(Main[ASIGNEE],J33) -> 2 | L33: =SUMIF(Main[ASIGNEE], J33, Main[DAYS REQUIRED]) -> 2 | M33: =AVERAGEIF(Main[ASIGNEE], J33, Main[PROGRESS]) -> 1 | N33: =IFERROR(1-M33,"") -> 0 | O33: =IF(K33>0, $K$3, "") -> 31
J34: =_xlfn.IFS(Data!M9<>0, Data!M9,Data!M9=0, #N/A) -> DEV | K34: =COUNTIF(Main[ASIGNEE],J34) -> 7 | L34: =SUMIF(Main[ASIGNEE], J34, Main[DAYS REQUIRED]) -> 20 | M34: =AVERAGEIF(Main[ASIGNEE], J34, Main[PROGRESS]) -> 0.5 | N34: =IFERROR(1-M34,"") -> 0.5 | O34: =IF(K34>0, $K$3, "") -> 31
J35: =_xlfn.IFS(Data!M25<>0, Data!M25,Data!M25=0, #N/A) | K35: =COUNTIF(Main[ASIGNEE],J35) -> 0 | L35: =SUMIF(Main[ASIGNEE], J35, Main[DAYS REQUIRED]) -> 0 | M35: =AVERAGEIF(Main[ASIGNEE], J35, Main[PROGRESS]) -> #DIV/0! | N35: =IFERROR(1-M35,"") | O35: =IF(K35>0, $K$3, "")
J36: =_xlfn.IFS(Data!M26<>0, Data!M26,Data!M26=0, #N/A) | K36: =COUNTIF(Main[ASIGNEE],J36) -> 0 | L36: =SUMIF(Main[ASIGNEE], J36, Main[DAYS REQUIRED]) -> 0 | M36: =AVERAGEIF(Main[ASIGNEE], J36, Main[PROGRESS]) -> #DIV/0! | N36: =IFERROR(1-M36,"") | O36: =IF(K36>0, $K$3, "")

Sheet DASHBOARD
E5: OVERDUE TASKS | I5: Today: | J5: =Data!O2 -> 45728
E8: PROJECT | F8: TASK | G8: ASIGNEE | H8: END DATE | I8: PROGRESS | J8: OVERDUE
E9: =Data!S14 | F9: =Data!T14 | G9: =Data!U14 | H9: =Data!X14 | I9: =Data!Y14 | J9: =$J$5-H9 -> #VALUE!
E10: =Data!S15 | F10: =Data!T15 | G10: =Data!U15 | H10: =Data!X15 | I10: =Data!Y15 | J10: =$J$5-H10 -> #VALUE!
E11: =Data!S16 | F11: =Data!T16 | G11: =Data!U16 | H11: =Data!X16 | I11: =Data!Y16 | J11: =$J$5-H11 -> #VALUE!
E12: =Data!S17 | F12: =Data!T17 | G12: =Data!U17 | H12: =Data!X17 | I12: =Data!Y17 | J12: =$J$5-H12 -> #VALUE!
E13: =Data!S18 | F13: =Data!T18 | G13: =Data!U18 | H13: =Data!X18 | I13: =Data!Y18 | J13: =$J$5-H13 -> #VALUE!
E14: =Data!S19 | F14: =Data!T19 | G14: =Data!U19 | H14: =Data!X19 | I14: =Data!Y19 | J14: =$J$5-H14 -> #VALUE!
